Workbook

Sheet Part II - EBITDA Data
A1: Year | B1: Quarter | C1: Operating Income ($m) | D1: D&A ($m) | E1: EBITDA ($m) | G1: Year | H1: Annual EBITDA ($m)
A2: 2016 | B2: 1 | C2: 649 | D2: 479 | E2: =($C2+$D2) -> 1128 | G2: 2016 | H2: =SUM(E2:E5) -> 6315
B3: 2 | C3: 1060 | D3: 491 | E3: =($C3+$D3) -> 1551 | G3: 2017 | H3: =SUM(E6:E9) -> 5647
B4: 3 | C4: 1624 | D4: 503 | E4: =($C4+$D4) -> 2127 | G4: 2018 | H4: =SUM(E10:E13) -> 5532
B5: 4 | C5: =4338-SUM(C2:C4) -> 1005 | D5: =1977-SUM(D2:D4) -> 504 | E5: =($C5+$D5) -> 1509 | G5: 2019 | H5: =SUM(E14:E17) -> 6589
A6: 2017 | B6: 1 | C6: 278 | D6: 518 | E6: =($C6+$D6) -> 796 | G6: 2020 | H6: =SUM(E18:E21) -> -3871
B7: 2 | C7: 1399 | D7: 536 | E7: =($C7+$D7) -> 1935 | G7: 2021 | H7: =SUM(E22:E25) -> 1463
B8: 3 | C8: 1092 | D8: 556 | E8: =($C8+$D8) -> 1648 | G8: 2022 | H8: =SUM(E26:E29) -> 4793
B9: 4 | C9: =3498-SUM(C6:C8) -> 729 | D9: =2149-SUM(D6:D8) -> 539 | E9: =($C9+$D9) -> 1268 | G9: 2023 | H9: =SUM(E30:E33) -> 6882
A10: 2018 | B10: 1 | C10: 276 | D10: 541 | E10: =($C10+$D10) -> 817 | G10: 2024 | H10: =SUM(E34:E37) -> 8024
B11: 2 | C11: 1161 | D11: 557 | E11: =($C11+$D11) -> 1718 | G11: 2025 | H11: =SUM(E38:E41) -> 7652
B12: 3 | C12: 1203 | D12: 564 | E12: =($C12+$D12) -> 1767
B13: 4 | C13: =3292-SUM(C10:C12) -> 652 | D13: =2240-SUM(D10:D12) -> 578 | E13: =($C13+$D13) -> 1230 | G13: Statistical Summary
A14: 2019 | B14: 1 | C14: 495 | D14: 547 | E14: =($C14+$D14) -> 1042 | G14: Count (n) | H14: =COUNT(H2:H11) -> 10
B15: 2 | C15: 1472 | D15: 560 | E15: =($C15+$D15) -> 2032 | G15: Mean ($m) | H15: =AVERAGE(H2:H11) -> 4902.6
B16: 3 | C16: 1473 | D16: 575 | E16: =($C16+$D16) -> 2048 | G16: Std Dev ($m) | H16: =STDEV(H2:H11) -> 3587.453
B17: 4 | C17: =4301-SUM(C14:C16) -> 861 | D17: =2288-SUM(D14:D16) -> 606 | E17: =($C17+$D17) -> 1467 | G17: Min ($m) | H17: =MIN(H2:H11) -> -3871
A18: 2020 | B18: 1 | C18: -972 | D18: 615 | E18: =($C18+$D18) -> -357 | G18: Max ($m) | H18: =MAX(H2:H11) -> 8024
B19: 2 | C19: -1637 | D19: 618 | E19: =($C19+$D19) -> -1019
B20: 3 | C20: -1615 | D20: 626 | E20: =($C20+$D20) -> -989
B21: 4 | C21: =-6359-SUM(C18:C20) -> -2135 | D21: =2488-SUM(D18:D20) -> 629 | E21: =($C21+$D21) -> -1506
A22: 2021 | B22: 1 | C22: -1381 | D22: 623 | E22: =($C22+$D22) -> -758
B23: 2 | C23: -270 | D23: 620 | E23: =($C23+$D23) -> 350
B24: 3 | C24: 1037 | D24: 623 | E24: =($C24+$D24) -> 1660
B25: 4 | C25: =-1022-SUM(C22:C24) -> -408 | D25: =2485-SUM(D22:D24) -> 619 | E25: =($C25+$D25) -> 211
A26: 2022 | B26: 1 | C26: -1376 | D26: 611 | E26: =($C26+$D26) -> -765
B27: 2 | C27: 878 | D27: 611 | E27: =($C27+$D27) -> 1489
B28: 3 | C28: 1458 | D28: 610 | E28: =($C28+$D28) -> 2068
B29: 4 | C29: =2337-SUM(C26:C28) -> 1377 | D29: =2456-SUM(D26:D28) -> 624 | E29: =($C29+$D29) -> 2001
A30: 2023 | B30: 1 | C30: -43 | D30: 655 | E30: =($C30+$D30) -> 612
B31: 2 | C31: 1517 | D31: 669 | E31: =($C31+$D31) -> 2186
B32: 3 | C32: 1739 | D32: 663 | E32: =($C32+$D32) -> 2402
B33: 4 | C33: =4211-SUM(C30:C32) -> 998 | D33: =2671-SUM(D30:D32) -> 684 | E33: =($C33+$D33) -> 1682
A34: 2024 | B34: 1 | C34: 99 | D34: 708 | E34: =($C34+$D34) -> 807
B35: 2 | C35: 1929 | D35: 719 | E35: =($C35+$D35) -> 2648
B36: 3 | C36: 1565 | D36: 742 | E36: =($C36+$D36) -> 2307
B37: 4 | C37: =5096-SUM(C34:C36) -> 1503 | D37: =2928-SUM(D34:D36) -> 759 | E37: =($C37+$D37) -> 2262
A38: 2025 | B38: 1 | C38: 607 | D38: 727 | E38: =($C38+$D38) -> 1334
B39: 2 | C39: 1325 | D39: 733 | E39: =($C39+$D39) -> 2058
B40: 3 | C40: 1395 | D40: 730 | E40: =($C40+$D40) -> 2125
...

Sheet Part I - EaR Calculation
A1: Part I: Earnings-at-Risk (EaR) Calculation — United Airlines 2026
A2: Confidence Level: 95% (One-Tailed) | Time Horizon: 1 Year
A4: Step 1: Annual EBITDA Data | B4: Annual EBITDA ($m) | C4: Source
A5: 2016 | B5: ='Part II - EBITDA Data'!H2 -> 6315 | C5: SEC 10-Q, Q1-Q4 2016
A6: 2017 | B6: ='Part II - EBITDA Data'!H3 -> 5647 | C6: SEC 10-Q, Q1-Q4 2017
A7: 2018 | B7: ='Part II - EBITDA Data'!H4 -> 5532 | C7: SEC 10-Q, Q1-Q4 2018
A8: 2019 | B8: ='Part II - EBITDA Data'!H5 -> 6589 | C8: SEC 10-Q, Q1-Q4 2019
A9: 2020 | B9: ='Part II - EBITDA Data'!H6 -> -3871 | C9: SEC 10-Q, Q1-Q4 2020
A10: 2021 | B10: ='Part II - EBITDA Data'!H7 -> 1463 | C10: SEC 10-Q, Q1-Q4 2021
A11: 2022 | B11: ='Part II - EBITDA Data'!H8 -> 4793 | C11: SEC 10-Q, Q1-Q4 2022
A12: 2023 | B12: ='Part II - EBITDA Data'!H9 -> 6882 | C12: SEC 10-Q, Q1-Q4 2023
A13: 2024 | B13: ='Part II - EBITDA Data'!H10 -> 8024 | C13: SEC 10-Q, Q1-Q4 2024
A14: 2025 | B14: ='Part II - EBITDA Data'!H11 -> 7652 | C14: SEC 10-Q, Q1-Q4 2025
A16: Step 2: Statistical Inputs | B16: Value | C16: Notes
A17: Number of Observations (n) | B17: =COUNT(B5:B14) -> 10 | C17: 10 annual data points (2016-2025)
A18: Mean Annual EBITDA ($m) | B18: =AVERAGE(B5:B14) -> 4902.6 | C18: Arithmetic mean of annual EBITDA
A19: Standard Deviation ($m) | B19: =STDEV(B5:B14) -> 3587.453 | C19: Sample std dev (n-1); measures earnings volatility
A20: Confidence Level | B20: 0.95 | C20: 95% one-tailed — standard EaR convention
A21: Z-Score (one-tailed, 95%) | B21: =NORMINV(B20,0,1) -> 1.6448536 | C21: NORMINV(Confidence Level, 0, 1); auto-calculated z-score
A23: Step 3: EaR Results | B23: Value ($m) | C23: Formula
A24: Expected 2026 EBITDA ($m) | B24: =B18 -> 4902.6 | C24: Mean Annual EBITDA
A25: Earnings-at-Risk — EaR ($m) | B25: =B21*B19 -> 5900.8352 | C25: Z-Score x Std Dev
A26: Worst-Case 2026 EBITDA ($m) | B26: =B24-B25 -> -998.23516 | C26: Expected EBITDA - EaR
A27: EaR as % of Expected EBITDA | B27: =IFERROR(B25/B24,0) -> 1.2036134 | C27: EaR / Expected EBITDA

Sheet Part IV - Economic Capital
A1: Part IV: Economic Capital (EC) Calculation — United Airlines
A2: Method: EaR-Based Top-Down Approach | Solvency Standard: AA-rated (99.86%)
A4: Step 1: Key Inputs (Linked from Part I - EaR Sheet) | B4: Value ($m) | C4: Source
A5: Mean Annual EBITDA ($m) | B5: ='Part I - EaR Calculation'!B18 -> 4902.6 | C5: Part I EaR Sheet - Step 2
A6: Standard Deviation ($m) | B6: ='Part I - EaR Calculation'!B19 -> 3587.453 | C6: Part I EaR Sheet - Step 2
A7: Expected 2026 EBITDA ($m) | B7: ='Part I - EaR Calculation'!B24 -> 4902.6 | C7: Part I EaR Sheet - Step 3
A8: EaR at 95% Confidence ($m) | B8: ='Part I - EaR Calculation'!B25 -> 5900.8352 | C8: Part I EaR Sheet - Step 3
A9: Worst-Case EBITDA ($m) | B9: ='Part I - EaR Calculation'!B26 -> -998.23516 | C9: Part I EaR Sheet - Step 3
A11: Step 2: EC Solvency Assumptions | B11: Value | C11: Notes
A12: Target Solvency Confidence | B12: 0.9986 | C12: AA-rated standard (99.86%)
A13: Z-Score for EC Level | B13: =NORMINV(B12,0,1) -> 2.9888823 | C13: NORMINV(Target Solvency Confidence, 0, 1); auto-calculated
A15: Step 3: Economic Capital Results | B15: Value ($m) | C15: Formula
A16: Economic Capital — EC ($m) | B16: =B13*B6 -> 10722.475 | C16: Z_EC x Std Dev
A17: EC as % of Expected EBITDA | B17: =IFERROR(B16/B7,0) -> 2.1870997 | C17: EC / Expected 2026 EBITDA
A18: EC Coverage Ratio (EC / EaR) | B18: =IFERROR(B16/B8,0) -> 1.8171114 | C18: EC / EaR at 95%
A19: Additional Buffer beyond EaR ($m) | B19: =B16-B8 -> 4821.6396 | C19: EC - EaR

Sheet Part IV - Sensitivity Analysis
A1: Part IV: Sensitivity Analysis of EaR and Economic Capital — United Airlines
A3: Table 1: EaR Sensitivity to Confidence Level (Std Dev held constant)
A4: Confidence Level | B4: Z-Score | C4: Std Dev ($m) | D4: EaR ($m) | E4: Expected EBITDA ($m) | F4: Worst-Case EBITDA ($m) | G4: EaR as % Expected
A5: 0.9 | B5: 1.282 | C5: ='Part I - EaR Calculation'!B19 -> 3587.453 | D5: =B5*C5 -> 4599.1148 | E5: ='Part I - EaR Calculation'!B24 -> 4902.6 | F5: =E5-D5 -> 303.48519 | G5: =IFERROR(D5/E5,0) -> 0.93809709
A6: 0.925 | B6: 1.44 | C6: ='Part I - EaR Calculation'!B19 -> 3587.453 | D6: =B6*C6 -> 5165.9324 | E6: ='Part I - EaR Calculation'!B24 -> 4902.6 | F6: =E6-D6 -> -263.33239 | G6: =IFERROR(D6/E6,0) -> 1.0537128
A7: 0.95 | B7: 1.645 | C7: ='Part I - EaR Calculation'!B19 -> 3587.453 | D7: =B7*C7 -> 5901.3603 | E7: ='Part I - EaR Calculation'!B24 -> 4902.6 | F7: =E7-D7 -> -998.76027 | G7: =IFERROR(D7/E7,0) -> 1.2037205
A8: 0.975 | B8: 1.96 | C8: ='Part I - EaR Calculation'!B19 -> 3587.453 | D8: =B8*C8 -> 7031.408 | E8: ='Part I - EaR Calculation'!B24 -> 4902.6 | F8: =E8-D8 -> -2128.808 | G8: =IFERROR(D8/E8,0) -> 1.4342202
A9: 0.99 | B9: 2.326 | C9: ='Part I - EaR Calculation'!B19 -> 3587.453 | D9: =B9*C9 -> 8344.4158 | E9: ='Part I - EaR Calculation'!B24 -> 4902.6 | F9: =E9-D9 -> -3441.8158 | G9: =IFERROR(D9/E9,0) -> 1.7020389
A10: 0.999 | B10: 3.09 | C10: ='Part I - EaR Calculation'!B19 -> 3587.453 | D10: =B10*C10 -> 11085.23 | E10: ='Part I - EaR Calculation'!B24 -> 4902.6 | F10: =E10-D10 -> -6182.6299 | G10: =IFERROR(D10/E10,0) -> 2.2610921
A13: Table 2: EaR Sensitivity to EBITDA Volatility (Z = 1.645, 95% Confidence)
A14: Scenario | B14: Std Dev ($m) | C14: Z-Score | D14: EaR ($m) | E14: Expected EBITDA ($m) | F14: Worst-Case EBITDA ($m) | G14: Notes
A15: Low Volatility (-30%) | B15: ='Part I - EaR Calculation'!B19*0.7 -> 2511.2171 | C15: 1.645 | D15: =B15*C15 -> 4130.9522 | E15: ='Part I - EaR Calculation'!B24 -> 4902.6 | F15: =E15-D15 -> 771.64781 | G15: Fuel costs stable; demand steady
A16: Moderate Low (-15%) | B16: ='Part I - EaR Calculation'!B19*0.85 -> 3049.3351 | C16: 1.645 | D16: =B16*C16 -> 5016.1562 | E16: ='Part I - EaR Calculation'!B24 -> 4902.6 | F16: =E16-D16 -> -113.55623 | G16: Mild improvement in stability
A17: Base Case (Actual) | B17: ='Part I - EaR Calculation'!B19 -> 3587.453 | C17: 1.645 | D17: =B17*C17 -> 5901.3603 | E17: ='Part I - EaR Calculation'!B24 -> 4902.6 | F17: =E17-D17 -> -998.76027 | G17: Actual historical std dev
A18: Moderate High (+15%) | B18: ='Part I - EaR Calculation'!B19*1.15 -> 4125.571 | C18: 1.645 | D18: =B18*C18 -> 6786.5643 | E18: ='Part I - EaR Calculation'!B24 -> 4902.6 | F18: =E18-D18 -> -1883.9643 | G18: Increased fuel/demand uncertainty
A19: High Volatility (+30%) | B19: ='Part I - EaR Calculation'!B19*1.3 -> 4663.689 | C19: 1.645 | D19: =B19*C19 -> 7671.7683 | E19: ='Part I - EaR Calculation'!B24 -> 4902.6 | F19: =E19-D19 -> -2769.1683 | G19: Severe macro or oil price shock
A22: Table 3: EC Sensitivity to Solvency Confidence Level
A23: Solvency Level | B23: Z-Score | C23: Std Dev ($m) | D23: Economic Capital ($m) | E23: EC as % Expected EBITDA | F23: EC / EaR Ratio | G23: Rating Equivalent
A24: 0.95 | B24: 1.645 | C24: ='Part I - EaR Calculation'!B19 -> 3587.453 | D24: =B24*C24 -> 5901.3603 | E24: =IFERROR(D24/'Part I - EaR Calculation'!B24,0) -> 1.2037205 | F24: =IFERROR(D24/'Part I - EaR Calculation'!B25,0) -> 1.000089 | G24: BBB / Investment Grade
A25: 0.99 | B25: 2.326 | C25: ='Part I - EaR Calculation'!B19 -> 3587.453 | D25: =B25*C25 -> 8344.4158 | E25: =IFERROR(D25/'Part I - EaR Calculation'!B24,0) -> 1.7020389 | F25: =IFERROR(D25/'Part I - EaR Calculation'!B25,0) -> 1.4141076 | G25: A / Strong Investment Grade
A26: 0.999 | B26: 3.09 | C26: ='Part I - EaR Calculation'!B19 -> 3587.453 | D26: =B26*C26 -> 11085.23 | E26: =IFERROR(D26/'Part I - EaR Calculation'!B24,0) -> 2.2610921 | F26: =IFERROR(D26/'Part I - EaR Calculation'!B25,0) -> 1.8785866 | G26: AA / Very Strong
A27: 0.9986 | B27: 3 | C27: ='Part I - EaR Calculation'!B19 -> 3587.453 | D27: =B27*C27 -> 10762.359 | E27: =IFERROR(D27/'Part I - EaR Calculation'!B24,0) -> 2.195235 | F27: =IFERROR(D27/'Part I - EaR Calculation'!B25,0) -> 1.8238705 | G27: AA Standard (Base Case)
A28: 0.9999 | B28: 3.719 | C28: ='Part I - EaR Calculation'!B19 -> 3587.453 | D28: =B28*C28 -> 13341.738 | E28: =IFERROR(D28/'Part I - EaR Calculation'!B24,0) -> 2.7213597 | F28: =IFERROR(D28/'Part I - EaR Calculation'!B25,0) -> 2.2609915 | G28: AAA / Highest Grade
